Workbook

Sheet DASHBOARD
A2: TOTAL DE INTERVENÇÕES 2026
A3: =Totais!M22 -> 150
K9: =+'Pedidos de Intervenção'!K192026 -> 0
L35: `

Sheet JAN
B1: Assistências Nas Escolas 2026
B3: JANEIRO
A4: Data Pedido | B4: Data | C4: Estabelecimento | D4: Freguesia | E4: Agrupamento | F4: Hardware | G4: Software | H4: Redes | I4: VPN | J4: AudioVisual | K4: Tipo de Intervenção | L4: Material Recolhido / Abatido
B5: 46027 | C5: EB1 Monte Real | E5: =IF(C5>0,LOOKUP(C5,'Lista de Escolas'!$C$3:$C$178,'Lista de Escolas'!$E$3:$E$178),"") -> Escolas Rainha Santa Isabel | H5: 1 | K5: Substituição de Access Point
B6: 46027 | C6: JI Ruivaqueira | E6: =IF(C6>0,LOOKUP(C6,'Lista de Escolas'!$C$3:$C$178,'Lista de Escolas'!$E$3:$E$178),"") -> Henrique Sommer | F6: 1 | H6: 1 | K6: Aberto pedido de reparação da internet junto da assistência técnica da Altice, substituição de Portátil
B7: 46028 | C7: EB1 Barreiros | E7: =IF(C7>0,LOOKUP(C7,'Lista de Escolas'!$C$3:$C$178,'Lista de Escolas'!$E$3:$E$178),"") -> Escolas Domingos Sequeira | I7: 1 | K7: configuração do portátil da VPN das auxiliares
B8: 46029 | C8: Eb1 Caxieira | E8: =IF(C8>0,LOOKUP(C8,'Lista de Escolas'!$C$3:$C$178,'Lista de Escolas'!$E$3:$E$178),"") -> Escolas Domingos Sequeira | H8: 1 | I8: 1 | K8: reinstalação e configuração de VPN, resoluição de problemas de acesso á internet num pc fixo
B9: 46029 | C9: Eb1 Bidoeira de Cima | E9: =IF(C9>0,LOOKUP(C9,'Lista de Escolas'!$C$3:$C$178,'Lista de Escolas'!$E$3:$E$178),"") -> Escolas Domingos Sequeira | H9: 1 | K9: avaliação de necessidades de rede wifi para a realização de projeto de programação em contexto de sala de aula
B10: 46029 | C10: JI Telheiro | E10: =IF(C10>0,LOOKUP(C10,'Lista de Escolas'!$C$3:$C$178,'Lista de Escolas'!$E$3:$E$178),"") -> Henrique Sommer | H10: 1 | K10: avaliação de necessidades de equipamento para passagem de rede para o pavilhão dfas AAAF
B11: 46030 | C11: EB1 Palmeiria | E11: =IF(C11>0,LOOKUP(C11,'Lista de Escolas'!$C$3:$C$178,'Lista de Escolas'!$E$3:$E$178),"") -> Escolas Rainha Santa Isabel | F11: 1 | K11: recolha de portátil para reparação
B12: 46030 | C12: JI Palmeiria | E12: =IF(C12>0,LOOKUP(C12,'Lista de Escolas'!$C$3:$C$178,'Lista de Escolas'!$E$3:$E$178),"") -> Henrique Sommer | F12: 1 | G12: 1 | K12: formatação e instalação de todo o software do portátil do JI
B13: 46030 | C13: EB1 Casal Novo | E13: =IF(C13>0,LOOKUP(C13,'Lista de Escolas'!$C$3:$C$178,'Lista de Escolas'!$E$3:$E$178),"") -> Escolas Domingos Sequeira | F13: 1 | G13: 1 | K13: recolha de computador para formatação e instalação de todo o software
B14: 46031 | C14: EB1 Monte Redondo | E14: =IF(C14>0,LOOKUP(C14,'Lista de Escolas'!$C$3:$C$176,'Lista de Escolas'!$E$3:$E$176),"") -> Escolas Rainha Santa Isabel | F14: 1 | J14: 1 | K14: recolha de pc para reparação, ligação de quadro interativo, configuração de impressoras
B15: 46031 | C15: JI Loureira | E15: =IF(C15>0,LOOKUP(C15,'Lista de Escolas'!$C$3:$C$176,'Lista de Escolas'!$E$3:$E$176),"") -> Escolas Rainha Santa Isabel | I15: 1 | K15: Configuração de vpn
B16: 46031 | C16: Eb1 Machados | E16: =IF(C16>0,LOOKUP(C16,'Lista de Escolas'!$C$3:$C$174,'Lista de Escolas'!$E$3:$E$174),"") -> Escolas Rainha Santa Isabel | F16: 1 | H16: 1 | K16: resolução de anomalias na internet, configuração de 2 access points, substituição do telefone
B17: 46031 | C17: EB1 Andrinos | E17: =IF(C17>0,LOOKUP(C17,'Lista de Escolas'!$C$3:$C$174,'Lista de Escolas'!$E$3:$E$174),"") -> Escolas Domingos Sequeira | F17: 1 | K17: recolha de pc para substituição de disco
B18: 46034 | C18: Ji Loureira | E18: =IF(C18>0,LOOKUP(C18,'Lista de Escolas'!$C$3:$C$174,'Lista de Escolas'!$E$3:$E$174),"") -> Escolas Rainha Santa Isabel | I18: 1 | K18: Verificação de anomalias no funcionamento do sftware de VPN
B19: 46034 | C19: EB1 Monte Redondo | E19: =IF(C19>0,LOOKUP(C19,'Lista de Escolas'!$C$3:$C$174,'Lista de Escolas'!$E$3:$E$174),"") -> Escolas Rainha Santa Isabel | F19: 1 | K19: recolha de computador para reparação
B20: 46034 | C20: EB1 Caranguejeira | E20: =IF(C20>0,LOOKUP(C20,'Lista de Escolas'!$C$3:$C$174,'Lista de Escolas'!$E$3:$E$174),"") -> Escolas Dr. Correia Mateus | H20: 1 | K20: Reparação de acesso à internet num computador fixo
B21: 46034 | C21: Eb1 Souto de cima | E21: =IF(C21>0,LOOKUP(C21,'Lista de Escolas'!$C$3:$C$174,'Lista de Escolas'!$E$3:$E$174),"") -> Escolas Rainha Santa Isabel | F21: 1 | I21: 1 | K21: avaliação das necessidades informáticas na sala 2, verificação de anomalias na vpn, e verificação de trackpad num portátil
B22: 46035 | C22: Eb1 Monte Redondo | E22: =IF(C22>0,LOOKUP(C22,'Lista de Escolas'!$C$3:$C$174,'Lista de Escolas'!$E$3:$E$174),"") -> Escolas Rainha Santa Isabel | F22: 1 | K22: entrega de computador reparado
B23: 46035 | C23: Eb1 Andrinos | E23: =IF(C23>0,LOOKUP(C23,'Lista de Escolas'!$C$3:$C$174,'Lista de Escolas'!$E$3:$E$174),"") -> Escolas Domingos Sequeira | F23: 1 | K23: entrega de computador reparado
B24: 46036 | C24: EB1 Barosa | E24: =IF(C24>0,LOOKUP(C24,'Lista de Escolas'!$C$3:$C$174,'Lista de Escolas'!$E$3:$E$174),"") -> Escolas Dr. Correia Mateus | F24: 1 | G24: 1 | K24: Recolha de 4 computadores para substituição de disscos, formatação e instalação de software
B25: 46038 | C25: EB1 Barosa | E25: =IF(C25>0,LOOKUP(C25,'Lista de Escolas'!$C$3:$C$174,'Lista de Escolas'!$E$3:$E$174),"") -> Escolas Dr. Correia Mateus | F25: 1 | G25: 1 | K25: entrega de 4 computadoes reparado e instalação de um monitor
B26: 46038 | C26: Eb1 Casal Novo | E26: =IF(C26>0,LOOKUP(C26,'Lista de Escolas'!$C$3:$C$174,'Lista de Escolas'!$E$3:$E$174),"") -> Escolas Dr. Correia Mateus | G26: 1 | H26: 1 | K26: Resolução de problemas no som do projetor
B27: 46038 | C27: EB1 Arrabal | E27: =IF(C27>0,LOOKUP(C27,'Lista de Escolas'!$C$3:$C$174,'Lista de Escolas'!$E$3:$E$174),"") -> Escolas Dr. Correia Mateus | F27: 1 | G27: 1 | K27: resolução de problemas de rede, reinstalação de drive de impressora
B28: 46038 | C28: EB1 Arrabalde | E28: =IF(C28>0,LOOKUP(C28,'Lista de Escolas'!$C$3:$C$174,'Lista de Escolas'!$E$3:$E$174),"") -> Escolas Dr. Correia Mateus | F28: 1 | G28: 1 | K28: Recolha de 4 computadores para substituição de disscos, formatação e instalação de software
B29: 46038 | C29: EB1 Branca | E29: =IF(C29>0,LOOKUP(C29,'Lista de Escolas'!$C$3:$C$174,'Lista de Escolas'!$E$3:$E$174),"") -> Escolas Dr. Correia Mateus | F29: 1 | H29: 1 | K29: Instalação de swith e access point para expansão da wan ao novo pavilhão da biblioteca, reparação de arranque de pc
B30: 46044 | C30: EB1 Reixida | E30: =IF(C30>0,LOOKUP(C30,'Lista de Escolas'!$C$3:$C$174,'Lista de Escolas'!$E$3:$E$174),"") -> Escolas Rainha Santa Isabel | F30: 1 | G30: 1 | K30: Recolha de dois comnputadores para subnstituir disco, formatação e instalação de software
B31: 46044 | C31: EB1 Arrabalde | E31: =IF(C31>0,LOOKUP(C31,'Lista de Escolas'!$C$3:$C$174,'Lista de Escolas'!$E$3:$E$174),"") -> Escolas Dr. Correia Mateus | F31: 1 | G31: 1 | K31: Entrega de 4 computadores reparados, configiuração de impressoras e acesso á redeqwireless
B32: 46044 | C32: Eb1 Capuchos | E32: =IF(C32>0,LOOKUP(C32,'Lista de Escolas'!$C$3:$C$174,'Lista de Escolas'!$E$3:$E$174),"") -> Escolas Dr. Correia Mateus | H32: 1 | K32: Avaliação de necessidade de equipamentos de rede para reparação de avaria
B33: 46044 | C33: Eb1 Branca | E33: =IF(C33>0,LOOKUP(C33,'Lista de Escolas'!$C$3:$C$174,'Lista de Escolas'!$E$3:$E$174),"") -> Escolas Dr. Correia Mateus | F33: 1 | J33: 1 | K33: substituição de monitor,instalaçãod e adaptador HDMI e splitter em quadro iteractivo, aajuste nos cabos monitor para melhoria de imagem
B34: 46045 | C34: JI Loureira | E34: =IF(C34>0,LOOKUP(C34,'Lista de Escolas'!$C$3:$C$174,'Lista de Escolas'!$E$3:$E$174),"") -> Escolas Rainha Santa Isabel | J34: 1 | K34: entrega de colunas novas
B35: 46045 | C35: EB1 Monte Redondo | E35: =IF(C35>0,LOOKUP(C35,'Lista de Escolas'!$C$3:$C$174,'Lista de Escolas'!$E$3:$E$174),"") -> Escolas Rainha Santa Isabel | G35: 1 | K35: configuração de acesso à impressora em todos os computadores
B36: 46045 | C36: Centro Escolar Maceira | E36: =IF(C36>0,LOOKUP(C36,'Lista de Escolas'!$C$3:$C$174,'Lista de Escolas'!$E$3:$E$174),"") -> #N/A | F36: 1 | G36: 1 | K36: resolução de problemas em dois quadros imnteractivos, ajustes de cabos e instalação de drives
B37: 46045 | C37: Ji A-dos-pretos | E37: =IF(C37>0,LOOKUP(C37,'Lista de Escolas'!$C$3:$C$174,'Lista de Escolas'!$E$3:$E$174),"") -> Escolas Rainha Santa Isabel | F37: 1 | G37: 1 | K37: Recolha de dois comnputadores para subnstituir disco, formatação e instalação de software
B38: 46045 | C38: EB1 Amarela | E38: =IF(C38>0,LOOKUP(C38,'Lista de Escolas'!$C$3:$C$174,'Lista de Escolas'!$E$3:$E$174),"") -> #N/A | F38: 1 | G38: 1 | K38: recolha de 5 computadores para substituição de disscos, formatação e instalação de software
B39: 46049 | C39: EB1 Capuchos | E39: =IF(C39>0,LOOKUP(C39,'Lista de Escolas'!$C$3:$C$174,'Lista de Escolas'!$E$3:$E$174),"") -> Escolas Dr. Correia Mateus | H39: 1 | K39: instalação de extensor de rede na sala 2
B40: 46049 | C40: Eb1 Souto da Carpalhosa | E40: =IF(C40>0,LOOKUP(C40,'Lista de Escolas'!$C$3:$C$174,'Lista de Escolas'!$E$3:$E$174),"") -> Escolas Rainha Santa Isabel | H40: 1 | K40: aferição de necessidades da mudança de linha do JI para o novo edificio
B41: 46049 | C41: JI Bairro das Almoinhas | E41: =IF(C41>0,LOOKUP(C41,'Lista de Escolas'!$C$3:$C$174,'Lista de Escolas'!$E$3:$E$174),"") -> Escolas Rainha Santa Isabel | H41: 1 | K41: aferição de necessidades de ligação da internet após obras
...

Sheet FEV
B1: Assistências Nas Escolas 2026
B3: FEVEREIRO
A4: Data Pedido | B4: Data | D4: Freguesia | E4: Agrupamento | F4: Hardware | G4: Software | H4: Redes | I4: VPN | J4: AudioVisual | K4: Tipo de Intervenção | L4: Material Recolhido / Abatido
B5: 46071 | C5: EB1 Monte Redondo | E5: =IF(C5>0,LOOKUP(C5,'Lista de Escolas'!$C$3:$C$178,'Lista de Escolas'!$E$3:$E$178),"") -> Escolas Rainha Santa Isabel | F5: 1 | K5: entrega de monitor novo, para substituir o que estava partido | L5: -
B6: 46073 | C6: EB1 Branca | E6: =IF(C6>0,LOOKUP(C6,'Lista de Escolas'!$C$3:$C$178,'Lista de Escolas'!$E$3:$E$178),"") -> Escolas Domingos Sequeira | F6: 1 | K6: substituição de módulo de memórias, atualização de sistema operativo | L6: -
B7: 46076 | C7: EB1 Outeiro da Fonte | E7: =IF(C7>0,LOOKUP(C7,'Lista de Escolas'!$C$3:$C$178,'Lista de Escolas'!$E$3:$E$178),"") -> Escolas Rainha Santa Isabel | F7: 1 | G7: 1 | K7: substituição de módulo de memórias, ativação do microsoft Office em 3 máquinas
B8: 46076 | C8: EB1 Barosa | E8: =IF(C8>0,LOOKUP(C8,'Lista de Escolas'!$C$3:$C$178,'Lista de Escolas'!$E$3:$E$178),"") -> Escolas D. Dinis | F8: 1 | K8: vedrificação de ligação á impressora
B9: 46079 | C9: EB1 Souto da Carpalhosa | E9: =IF(C9>0,LOOKUP(C9,'Lista de Escolas'!$C$3:$C$178,'Lista de Escolas'!$E$3:$E$178),"") -> Escolas Rainha Santa Isabel | H9: 1 | K9: verificação do acesso à internet, ligação dos equipamentos ativos de rede, e aberto pedido de intervenção junto do NSO
B10: 46079 | C10: EB1 Branca | E10: =IF(C10>0,LOOKUP(C10,'Lista de Escolas'!$C$3:$C$178,'Lista de Escolas'!$E$3:$E$178),"") -> Escolas Domingos Sequeira | H10: 1 | K10: instalação de switch para deistribuição da rede para os diversos access points
B11: 46080 | C11: EB1 Outeiro da Fonte | E11: =IF(C11>0,LOOKUP(C11,'Lista de Escolas'!$C$3:$C$178,'Lista de Escolas'!$E$3:$E$178),"") -> Escolas Rainha Santa Isabel | G11: 1 | K11: configuração de duas impressoras
B12: 46080 | C12: EB1 Chãs | E12: =IF(C12>0,LOOKUP(C12,'Lista de Escolas'!$C$3:$C$178,'Lista de Escolas'!$E$3:$E$178),"") -> Escolas Domingos Sequeira | F12: 1 | G12: 1 | I12: 1 | K12: entrega e configuração vpn no portatil para acesso à plataforma de assiduidade
B13: 46080 | C13: EB1 Souto do Meio | E13: =IF(C13>0,LOOKUP(C13,'Lista de Escolas'!$C$3:$C$178,'Lista de Escolas'!$E$3:$E$178),"") -> Escolas Rainha Santa Isabel | F13: 1 | K13: entrega de um pc reparado
B14: 46080 | C14: EB1 Reixida | E14: =IF(C14>0,LOOKUP(C14,'Lista de Escolas'!$C$3:$C$178,'Lista de Escolas'!$E$3:$E$178),"") -> Escolas Rainha Santa Isabel | F14: 1 | K14: entrega de dois computadores reparados
B15: 46080 | C15: EB1 Guimarota | E15: =IF(C15>0,LOOKUP(C15,'Lista de Escolas'!$C$3:$C$178,'Lista de Escolas'!$E$3:$E$178),"") -> Escolas Domingos Sequeira | F15: 1 | K15: recolha de 4 computadores para reparação
E16: =IF(C16>0,LOOKUP(C16,'Lista de Escolas'!$C$3:$C$178,'Lista de Escolas'!$E$3:$E$178),"")
E17: =IF(C17>0,LOOKUP(C17,'Lista de Escolas'!$C$3:$C$178,'Lista de Escolas'!$E$3:$E$178),"")
E18: =IF(C18>0,LOOKUP(C18,'Lista de Escolas'!$C$3:$C$178,'Lista de Escolas'!$E$3:$E$178),"")
E19: =IF(C19>0,LOOKUP(C19,'Lista de Escolas'!$C$3:$C$178,'Lista de Escolas'!$E$3:$E$178),"")
E20: =IF(C20>0,LOOKUP(C20,'Lista de Escolas'!$C$3:$C$178,'Lista de Escolas'!$E$3:$E$178),"")
E21: =IF(C21>0,LOOKUP(C21,'Lista de Escolas'!$C$3:$C$178,'Lista de Escolas'!$E$3:$E$178),"")
E22: =IF(C22>0,LOOKUP(C22,'Lista de Escolas'!$C$3:$C$178,'Lista de Escolas'!$E$3:$E$178),"")
E23: =IF(C23>0,LOOKUP(C23,'Lista de Escolas'!$C$3:$C$178,'Lista de Escolas'!$E$3:$E$178),"")
E24: =IF(C24>0,LOOKUP(C24,'Lista de Escolas'!$C$3:$C$178,'Lista de Escolas'!$E$3:$E$178),"")
E25: =IF(C25>0,LOOKUP(C25,'Lista de Escolas'!$C$3:$C$178,'Lista de Escolas'!$E$3:$E$178),"")
E26: =IF(C26>0,LOOKUP(C26,'Lista de Escolas'!$C$3:$C$178,'Lista de Escolas'!$E$3:$E$178),"")
E27: =IF(C27>0,LOOKUP(C27,'Lista de Escolas'!$C$3:$C$178,'Lista de Escolas'!$E$3:$E$178),"")
... E51: =IF(C51>0,LOOKUP(C51,'Lista de Escolas'!$C$3:$C$178,'Lista de Escolas'!$E$3:$E$178),"")
E52: =IF(C53>0,LOOKUP(C53,'Lista de Escolas'!$C$3:$C$178,'Lista de Escolas'!$E$3:$E$178),"")
E53: =IF(C54>0,LOOKUP(C54,'Lista de Escolas'!$C$3:$C$178,'Lista de Escolas'!$E$3:$E$178),"")
E54: =IF(C55>0,LOOKUP(C55,'Lista de Escolas'!$C$3:$C$178,'Lista de Escolas'!$E$3:$E$178),"")
E55: =IF(C55>0,LOOKUP(C55,'Lista de Escolas'!$C$3:$C$178,'Lista de Escolas'!$E$3:$E$178),"")
E56: =IF(C56>0,LOOKUP(C56,'Lista de Escolas'!$C$3:$C$178,'Lista de Escolas'!$E$3:$E$178),"")
E57: =IF(C57>0,LOOKUP(C57,'Lista de Escolas'!$C$3:$C$178,'Lista de Escolas'!$E$3:$E$178),"")
E58: =IF(C58>0,LOOKUP(C58,'Lista de Escolas'!$C$3:$C$178,'Lista de Escolas'!$E$3:$E$178),"")
E59: =IF(C59>0,LOOKUP(C59,'Lista de Escolas'!$C$3:$C$178,'Lista de Escolas'!$E$3:$E$178),"")
E60: =IF(C60>0,LOOKUP(C60,'Lista de Escolas'!$C$3:$C$178,'Lista de Escolas'!$E$3:$E$178),"")
E61: =IF(C61>0,LOOKUP(C61,'Lista de Escolas'!$C$3:$C$178,'Lista de Escolas'!$E$3:$E$178),"")
E62: =IF(C62>0,LOOKUP(C62,'Lista de Escolas'!$C$3:$C$178,'Lista de Escolas'!$E$3:$E$178),"")
E63: =IF(C63>0,LOOKUP(C63,'Lista de Escolas'!$C$3:$C$178,'Lista de Escolas'!$E$3:$E$178),"")
E64: =IF(C64>0,LOOKUP(C64,'Lista de Escolas'!$C$3:$C$178,'Lista de Escolas'!$E$3:$E$178),"")
...

Sheet MAR
B1: Assistências Nas Escolas 2026
B3: MARÇO
A4: Data Pedido | B4: Data | C4: Estabelecimento | D4: Freguesia | E4: Agrupamento | F4: Hardware | G4: Software | H4: Redes | I4: VPN | J4: AudioVisual | K4: Tipo de Intervenção | L4: Material Recolhido / Abatido
B5: 46083 | C5: EB1 Sismaria | E5: =IF(C5>0,LOOKUP(C5,'Lista de Escolas'!$C$2:$C$181,'Lista de Escolas'!$E$2:$E$181),"") -> Escolas Rainha Santa Isabel | H5: 1 | K5: verificação do estado do acesso à internet, abertura de ticket junto do NSO
B6: 46083 | C6: JI Bairro das Almoinhas | E6: =IF(C6>0,LOOKUP(C6,'Lista de Escolas'!$C$2:$C$181,'Lista de Escolas'!$E$2:$E$181),"") -> Escolas Rainha Santa Isabel | H6: 1 | K6: verificação do estado do acesso à internet, abertura de ticket junto do MEO EMPRESAS
B7: 46083 | C7: Ji A-dos-Pretos | E7: =IF(C7>0,LOOKUP(C7,'Lista de Escolas'!$C$2:$C$181,'Lista de Escolas'!$E$2:$E$181),"") -> Escolas Rainha Santa Isabel | F7: 1 | K7: entrega de dois copmputadores reparados
B8: 46083 | C8: EB1 Marinheiros | E8: =IF(C8>0,LOOKUP(C8,'Lista de Escolas'!$C$2:$C$181,'Lista de Escolas'!$E$2:$E$181),"") -> Escolas Domingos Sequeira | F8: 1 | G8: 1 | K8: recolha de pc para substituição de disco e instalação de todo o software
B9: 46083 | C9: EB1 Guimarota | E9: =IF(C9>0,LOOKUP(C9,'Lista de Escolas'!$C$2:$C$181,'Lista de Escolas'!$E$2:$E$181),"") -> Escolas Domingos Sequeira | F9: 1 | K9: entrega e instalação de 4 computadores reparados
B10: 46083 | C10: JI Guimarota | E10: =IF(C10>0,LOOKUP(C10,'Lista de Escolas'!$C$2:$C$181,'Lista de Escolas'!$E$2:$E$181),"") -> Escolas Rainha Santa Isabel | H10: 1 | K10: verificação de acesso à interner, abertura de ticket junto da MEO EMPRESAS
B11: 46085 | C11: JI Santa Catarina da Serra | E11: =IF(C11>0,LOOKUP(C11,'Lista de Escolas'!$C$2:$C$181,'Lista de Escolas'!$E$2:$E$181),"") -> Henrique Sommer | F11: 1 | K11: recolha de monitor para substituição | L11: -
B12: 46087 | C12: JI Santa Catarina da Serra | E12: =IF(C12>0,LOOKUP(C12,'Lista de Escolas'!$C$2:$C$181,'Lista de Escolas'!$E$2:$E$181),"") -> Henrique Sommer | F12: 1 | K12: entrega de computador reparado e monitor
B13: 46087 | C13: ji Outeiro da Fonte | E13: =IF(C13>0,LOOKUP(C13,'Lista de Escolas'!$C$2:$C$181,'Lista de Escolas'!$E$2:$E$181),"") -> Escolas Rainha Santa Isabel | F13: 1 | K13: verificação de anomalia no arranque de um pc
B14: 46090 | C14: JI Telheiro | E14: =IF(C14>0,LOOKUP(C14,'Lista de Escolas'!$C$2:$C$181,'Lista de Escolas'!$E$2:$E$181),"") -> Henrique Sommer | H14: 1 | K14: ligação de pc à internet, aferição de necessidades de passagem de cabo de rede para a AAAF
B15: 46090 | C15: EB1 lameira | E15: =IF(C15>0,LOOKUP(C15,'Lista de Escolas'!$C$2:$C$181,'Lista de Escolas'!$E$2:$E$181),"") -> Escolas Domingos Sequeira | H15: 1 | K15: passagem de cabo de rede entre salas, e comunicação ao NSO de falta de internet | L15: -
B16: 46090 | C16: EB1 Capuchos | E16: =IF(C16>0,LOOKUP(C16,'Lista de Escolas'!$C$2:$C$181,'Lista de Escolas'!$E$2:$E$181),"") -> Escolas da Caranguejeira - Santa Catarina da Serra | H16: 1 | K16: substituição de cabo de rede para a sala do R/C | L16: -
B17: 46091 | C17: EB1 Guimarota | E17: =IF(C17>0,LOOKUP(C17,'Lista de Escolas'!$C$2:$C$181,'Lista de Escolas'!$E$2:$E$181),"") -> Escolas Domingos Sequeira | F17: 1 | K17: entrega de doias ratos | L17: -
B18: 46091 | C18: EB1 Amarela | E18: =IF(C18>0,LOOKUP(C18,'Lista de Escolas'!$C$2:$C$181,'Lista de Escolas'!$E$2:$E$181),"") -> Escolas D. Dinis | F18: 1 | H18: 1 | I18: 1 | K18: entrega de 4 pc's reparados, instalalação de vpn, reconfiguração de ap's | L18: -
B19: 46094 | C19: EB1 Casal Novo | E19: =IF(C19>0,LOOKUP(C19,'Lista de Escolas'!$C$2:$C$181,'Lista de Escolas'!$E$2:$E$181),"") -> Escolas da Caranguejeira - Santa Catarina da Serra | F19: 1 | K19: ajuste de memórias na board | L19: -
B20: 46094 | C20: EB1 Barreiros | E20: =IF(C20>0,LOOKUP(C20,'Lista de Escolas'!$C$2:$C$181,'Lista de Escolas'!$E$2:$E$181),"") -> Escolas D. Dinis | I20: 1 | K20: reinstalação e configuração do software da vpn em dois pcs
B21: 46100 | C21: EB1 Porto Carro | E21: =IF(C21>0,LOOKUP(C21,'Lista de Escolas'!$C$2:$C$181,'Lista de Escolas'!$E$2:$E$181),"") -> Escolas Rainha Santa Isabel | F21: 1 | K21: recolha de computador para reparar | L21: -
B22: 46100 | C22: EB1 A-Dos-Pretos | E22: =IF(C22>0,LOOKUP(C22,'Lista de Escolas'!$C$2:$C$181,'Lista de Escolas'!$E$2:$E$181),"") -> #N/A | F22: 1 | K22: recolha de pc para reparar
B23: 46100 | C23: ji Outeiro da Fonte | E23: =IF(C23>0,LOOKUP(C23,'Lista de Escolas'!$C$2:$C$181,'Lista de Escolas'!$E$2:$E$181),"") -> Escolas Rainha Santa Isabel | F23: 1 | K23: recolha de pc para reparar
B24: 46104 | C24: EB1 Porto Carro | E24: =IF(C24>0,LOOKUP(C24,'Lista de Escolas'!$C$2:$C$181,'Lista de Escolas'!$E$2:$E$181),"") -> Escolas Rainha Santa Isabel | F24: 1 | K24: Entrega de pc reparado, configuração de colunas
B25: 46104 | C25: EB1 A-Dos-Pretos | E25: =IF(C25>0,LOOKUP(C25,'Lista de Escolas'!$C$2:$C$181,'Lista de Escolas'!$E$2:$E$181),"") -> #N/A | F25: 1 | K25: entrega de pc reparado e conjunto novo (pc+monitor+teclado e rato)
B26: 46104 | C26: EB1 Bajouca | E26: =IF(C26>0,LOOKUP(C26,'Lista de Escolas'!$C$2:$C$181,'Lista de Escolas'!$E$2:$E$181),"") -> Escolas D. Dinis | G26: 1 | K26: configuração de fotocopiadora em todos os computadores
B27: 46104 | C27: EB1 Marinheiros | E27: =IF(C27>0,LOOKUP(C27,'Lista de Escolas'!$C$2:$C$181,'Lista de Escolas'!$E$2:$E$181),"") -> Escolas Domingos Sequeira | F27: 1 | K27: entrega de pc reparado
B28: 46105 | C28: EB1 Moita da Roda | E28: =IF(C28>0,LOOKUP(C28,'Lista de Escolas'!$C$2:$C$181,'Lista de Escolas'!$E$2:$E$181),"") -> Escolas Rainha Santa Isabel | H28: 1 | K28: cravar fichas no cabo de rede que vai para o edificio das AAAF, reparação de cabo de rede que ligava à fotocopiadora
B29: 46105 | C29: EB1 Outeiro da Fonte | E29: =IF(C29>0,LOOKUP(C29,'Lista de Escolas'!$C$2:$C$181,'Lista de Escolas'!$E$2:$E$181),"") -> Escolas Rainha Santa Isabel | F29: 1 | K29: reparação de pc
B30: 46105 | C30: EB1 Casal Novo | E30: =IF(C30>0,LOOKUP(C30,'Lista de Escolas'!$C$2:$C$181,'Lista de Escolas'!$E$2:$E$181),"") -> Escolas da Caranguejeira - Santa Catarina da Serra | F30: 1 | K30: reparação de pc, ajustes das memórias, limpeza interna
B31: 46105 | C31: JI Telheiro | E31: =IF(C31>0,LOOKUP(C31,'Lista de Escolas'!$C$2:$C$181,'Lista de Escolas'!$E$2:$E$181),"") -> Henrique Sommer | H31: 1 | K31: instalação de switch para passar o sinal de rede para o edificio das AAAF
B32: 46105 | C32: ji Outeiro da Fonte | E32: =IF(C32>0,LOOKUP(C32,'Lista de Escolas'!$C$2:$C$181,'Lista de Escolas'!$E$2:$E$181),"") -> Escolas Rainha Santa Isabel | F32: 1 | K32: entrega de computador reparado
B33: 46106 | C33: EB1 Outeiro da Fonte | E33: =IF(C33>0,LOOKUP(C33,'Lista de Escolas'!$C$2:$C$181,'Lista de Escolas'!$E$2:$E$181),"") -> Escolas Rainha Santa Isabel | F33: 1 | K33: substituição de emódulos de memória
B34: 46106 | C34: EB1 Bajouca | E34: =IF(C34>0,LOOKUP(C34,'Lista de Escolas'!$C$2:$C$181,'Lista de Escolas'!$E$2:$E$181),"") -> Escolas D. Dinis | G34: 1 | H34: 1 | K34: reinstalação de drives da fotocopiadora departamental, reconfigurasção de configurações de rede num pc
B35: 46106 | C35: EB1 Bouça | E35: =IF(C35>0,LOOKUP(C35,'Lista de Escolas'!$C$2:$C$181,'Lista de Escolas'!$E$2:$E$181),"") -> Escolas D. Dinis | H35: 1 | K35: avaliação das cominicações da internet, entrada da fibra na escola
B36: 46107 | C36: EB1 Amarela | E36: =IF(C36>0,LOOKUP(C36,'Lista de Escolas'!$C$2:$C$181,'Lista de Escolas'!$E$2:$E$181),"") -> Escolas D. Dinis | F36: 1 | K36: substituição de colunas
B37: 46111 | C37: EB1 Monte Real | E37: =IF(C37>0,LOOKUP(C37,'Lista de Escolas'!$C$2:$C$181,'Lista de Escolas'!$E$2:$E$181),"") -> Escolas Rainha Santa Isabel | F37: 1 | H37: 1 | K37: instalação de acess point. Verificação dos modelos dos portateis com transformadores avariados
B38: 46111 | C38: EB1 Souto da carpalhosa | E38: =IF(C38>0,LOOKUP(C38,'Lista de Escolas'!$C$2:$C$181,'Lista de Escolas'!$E$2:$E$181),"") -> Escolas Rainha Santa Isabel | F38: 1 | H38: 1 | K38: veriricação do acesso à internet, ligação de impressora à rede da escola
B39: 46111 | C39: JI Souto da Carpalhosa | E39: =IF(C39>0,LOOKUP(C39,'Lista de Escolas'!$C$2:$C$181,'Lista de Escolas'!$E$2:$E$181),"") -> Henrique Sommer | H39: 1 | K39: vrtificação do acesso à internet, e aferição das necessidades para distribuição
B40: 46111 | C40: EB1 Courelas | E40: =IF(C40>0,LOOKUP(C40,'Lista de Escolas'!$C$2:$C$181,'Lista de Escolas'!$E$2:$E$181),"") -> Escolas Domingos Sequeira | F40: 1 | K40: entrega de 2 conjuntos (pc + monitor + teclado + rato)
B41: 46112 | C41: EB1 Courelas | E41: =IF(C41>0,LOOKUP(C41,'Lista de Escolas'!$C$2:$C$181,'Lista de Escolas'!$E$2:$E$181),"") -> Escolas Domingos Sequeira | F41: 1 | K41: emtrega de dois computadores reparados
...

Sheet ABR
B1: Assistências Nas Escolas 2026
B3: ABRIL
A4: Data Pedido | B4: Data | C4: Estabelecimento | D4: Freguesia | E4: Agrupamento | F4: Hardware | G4: Software | H4: Redes | I4: VPN | J4: AudioVisual | K4: Tipo de Intervenção | L4: Material Recolhido / Abatido
B5: 46113 | C5: EB1 Bajouca | E5: =IF(C5>0,LOOKUP(C5,'Lista de Escolas'!$C$2:$C$181,'Lista de Escolas'!$E$2:$E$181),"") -> Escolas D. Dinis | H5: 1 | K5: reset e reconfiguração dos access points das salas
B6: 46113 | C6: EB1 Outeiro da Fonte | E6: =IF(C6>0,LOOKUP(C6,'Lista de Escolas'!$C$2:$C$181,'Lista de Escolas'!$E$2:$E$181),"") -> Escolas Rainha Santa Isabel | F6: 1 | K6: substituição de módulos de memória em 2 pc's
B7: 46113 | C7: EB1 Andrinos | E7: =IF(C7>0,LOOKUP(C7,'Lista de Escolas'!$C$2:$C$181,'Lista de Escolas'!$E$2:$E$181),"") -> Escolas D. Dinis | H7: 1 | K7: verificação do acesso á internet
B8: 46118 | C8: JI Amor | E8: =IF(C8>0,LOOKUP(C8,'Lista de Escolas'!$C$2:$C$181,'Lista de Escolas'!$E$2:$E$181),"") -> Escolas Rainha Santa Isabel | H8: 1 | K8: verificação de acesso à internet
B9: 46118 | C9: JI Monte Real | E9: =IF(C9>0,LOOKUP(C9,'Lista de Escolas'!$C$2:$C$181,'Lista de Escolas'!$E$2:$E$181),"") -> Escolas Rainha Santa Isabel | H9: 1 | K9: verificação de acesso à internet
B10: 46121 | C10: EB1 Monte Real | E10: =IF(C10>0,LOOKUP(C10,'Lista de Escolas'!$C$2:$C$181,'Lista de Escolas'!$E$2:$E$181),"") -> Escolas Rainha Santa Isabel | H10: 1 | K10: instalação de access point
B11: 46125 | C11: JI Souto da Carpalhosa | E11: =IF(C11>0,LOOKUP(C11,'Lista de Escolas'!$C$2:$C$181,'Lista de Escolas'!$E$2:$E$181),"") -> Henrique Sommer | H11: 1 | K11: passagem de cavo de rede do router para o switch, reparação de 3 cabos de rede
B12: 46125 | C12: EB1 Serra de Porto Urso | E12: =IF(C12>0,LOOKUP(C12,'Lista de Escolas'!$C$2:$C$181,'Lista de Escolas'!$E$2:$E$181),"") -> Escolas Rainha Santa Isabel | H12: 1 | K12: resolução de problemas no telefone
B13: 46125 | C13: EB1 Souto da Carpalhosa | E13: =IF(C13>0,LOOKUP(C13,'Lista de Escolas'!$C$2:$C$181,'Lista de Escolas'!$E$2:$E$181),"") -> Escolas Rainha Santa Isabel | H13: 1 | K13: substituição de telefone
B14: 46126 | C14: Ji Santa Catarina da Serra | E14: =IF(C14>0,LOOKUP(C14,'Lista de Escolas'!$C$2:$C$181,'Lista de Escolas'!$E$2:$E$181),"") -> Henrique Sommer | G14: 1 | H14: 1 | K14: verificação do acesso á internet , configuração de impressora
B15: 46126 | C15: EB1 Bajouca | E15: =IF(C15>0,LOOKUP(C15,'Lista de Escolas'!$C$2:$C$181,'Lista de Escolas'!$E$2:$E$181),"") -> Escolas D. Dinis | G15: 1 | K15: Instalação e configuração de impressora
B16: 46126 | C16: EB1 Souto da Carpalhosa | E16: =IF(C16>0,LOOKUP(C16,'Lista de Escolas'!$C$2:$C$181,'Lista de Escolas'!$E$2:$E$181),"") -> Escolas Rainha Santa Isabel | F16: 1 | K16: substituição de cabo do atendedor do telefone fixo
B17: 46134 | C17: JI Monte Real | E17: =IF(C17>0,LOOKUP(C17,'Lista de Escolas'!$C$2:$C$181,'Lista de Escolas'!$E$2:$E$181),"") -> Escolas Rainha Santa Isabel | H17: 1 | K17: verificação da ligação à internet, abertura de pedido de intervenção junto da Altice
B18: 46135 | C18: EB1 Carreira | E18: =IF(C18>0,LOOKUP(C18,'Lista de Escolas'!$C$2:$C$181,'Lista de Escolas'!$E$2:$E$181),"") -> Escolas da Caranguejeira - Santa Catarina da Serra | G18: 1 | K18: configuração de fotocopiadora em todos os pcs
B19: 46135 | C19: EB1 Andrinos | E19: =IF(C19>0,LOOKUP(C19,'Lista de Escolas'!$C$2:$C$181,'Lista de Escolas'!$E$2:$E$181),"") -> Escolas D. Dinis | F19: 1 | K19: entrega de 2 conuntos completos (pc + monitor + teclado + rato)
B20: 46136 | C20: EB1 Santa Catarina da Serra | E20: =IF(C20>0,LOOKUP(C20,'Lista de Escolas'!$C$2:$C$181,'Lista de Escolas'!$E$2:$E$181),"") -> Escolas Rainha Santa Isabel | F20: 1 | K20: recolha de pc para reparação
B21: 46139 | C21: EB1 Santa Catarina da Serra | E21: =IF(C21>0,LOOKUP(C21,'Lista de Escolas'!$C$2:$C$181,'Lista de Escolas'!$E$2:$E$181),"") -> Escolas Rainha Santa Isabel | F21: 1 | K21: entrega de computador reparado
B22: 46139 | C22: EB1 Marinheiros | E22: =IF(C22>0,LOOKUP(C22,'Lista de Escolas'!$C$2:$C$181,'Lista de Escolas'!$E$2:$E$181),"") -> Escolas Domingos Sequeira | F22: 1 | I22: 1 | K22: recolha de pc para reparação e reconfiguração de VPN
B23: 46139 | C23: JI Andrinos | E23: =IF(C23>0,LOOKUP(C23,'Lista de Escolas'!$C$2:$C$181,'Lista de Escolas'!$E$2:$E$181),"") -> Escolas Rainha Santa Isabel | F23: 1 | K23: Entrega de conjunto (monitor + computador + teclado + rato)
B24: 46141 | C24: EB1 Amarela | E24: =IF(C24>0,LOOKUP(C24,'Lista de Escolas'!$C$2:$C$181,'Lista de Escolas'!$E$2:$E$181),"") -> Escolas D. Dinis | F24: 1 | J24: 1 | K24: recolha de pc para reparação, entrega de pc reparado, configuração de quadros interativos
B25: 46142 | C25: EB1 Arrabalde | E25: =IF(C25>0,LOOKUP(C25,'Lista de Escolas'!$C$2:$C$181,'Lista de Escolas'!$E$2:$E$181),"") -> Escolas D. Dinis | I25: 1 | K25: instalação e configureação de vpn
E26: =IF(C26>0,LOOKUP(C26,'Lista de Escolas'!$C$2:$C$181,'Lista de Escolas'!$E$2:$E$181),"")
E27: =IF(C27>0,LOOKUP(C27,'Lista de Escolas'!$C$2:$C$181,'Lista de Escolas'!$E$2:$E$181),"")
E28: =IF(C28>0,LOOKUP(C28,'Lista de Escolas'!$C$2:$C$181,'Lista de Escolas'!$E$2:$E$181),"")
E29: =IF(C29>0,LOOKUP(C29,'Lista de Escolas'!$C$2:$C$181,'Lista de Escolas'!$E$2:$E$181),"")
E30: =IF(C30>0,LOOKUP(C30,'Lista de Escolas'!$C$2:$C$181,'Lista de Escolas'!$E$2:$E$181),"")
E31: =IF(C31>0,LOOKUP(C31,'Lista de Escolas'!$C$3:$C$181,'Lista de Escolas'!$E$3:$E$181),"")
E32: =IF(C32>0,LOOKUP(C32,'Lista de Escolas'!$C$3:$C$181,'Lista de Escolas'!$E$3:$E$181),"")
E33: =IF(C33>0,LOOKUP(C33,'Lista de Escolas'!$C$3:$C$181,'Lista de Escolas'!$E$3:$E$181),"")
E34: =IF(C34>0,LOOKUP(C34,'Lista de Escolas'!$C$3:$C$181,'Lista de Escolas'!$E$3:$E$181),"")
E35: =IF(C35>0,LOOKUP(C35,'Lista de Escolas'!$C$3:$C$181,'Lista de Escolas'!$E$3:$E$181),"")
E36: =IF(C36>0,LOOKUP(C36,'Lista de Escolas'!$C$3:$C$181,'Lista de Escolas'!$E$3:$E$181),"")
E37: =IF(C37>0,LOOKUP(C37,'Lista de Escolas'!$C$3:$C$181,'Lista de Escolas'!$E$3:$E$181),"")
E38: =IF(C38>0,LOOKUP(C38,'Lista de Escolas'!$C$3:$C$181,'Lista de Escolas'!$E$3:$E$181),"")
E39: =IF(C39>0,LOOKUP(C39,'Lista de Escolas'!$C$3:$C$181,'Lista de Escolas'!$E$3:$E$181),"")
E40: =IF(C40>0,LOOKUP(C40,'Lista de Escolas'!$C$3:$C$181,'Lista de Escolas'!$E$3:$E$181),"")
E41: =IF(C41>0,LOOKUP(C41,'Lista de Escolas'!$C$3:$C$181,'Lista de Escolas'!$E$3:$E$181),"")
...

Sheet MAI
B1: Assistências Nas Escolas 2026
B3: MAIO
A4: Data Pedido | B4: Data | C4: Estabelecimento | D4: Freguesia | E4: Agrupamento | F4: Hardware | G4: Software | H4: Redes | I4: VPN | J4: AudioVisual | K4: Tipo de Intervenção | L4: Material Recolhido / Abatido
B5: 46146 | C5: EB1 St. Catarina da Serra | E5: =IF(C5>0,LOOKUP(C5,'Lista de Escolas'!$C$3:$C$181,'Lista de Escolas'!$E$3:$E$181),"") -> Escolas Rainha Santa Isabel | F5: 1 | K5: entrega e instalação de computador reparado
B6: 46146 | C6: EB1 Monte redondo | E6: =IF(C6>0,LOOKUP(C6,'Lista de Escolas'!$C$3:$C$181,'Lista de Escolas'!$E$3:$E$181),"") -> Escolas Rainha Santa Isabel | F6: 1 | K6: reparação de computador, substituição de memórias, limpeza interna de componentes
B7: 46146 | C7: JI Monte Real | E7: =IF(C7>0,LOOKUP(C7,'Lista de Escolas'!$C$3:$C$181,'Lista de Escolas'!$E$3:$E$181),"") -> Escolas Rainha Santa Isabel | H7: 1 | K7: verificação do acesso à internet
B8: 46147 | C8: Eb1 machados | E8: =IF(C8>0,LOOKUP(C8,'Lista de Escolas'!$C$3:$C$178,'Lista de Escolas'!$E$3:$E$178),"") -> Escolas Rainha Santa Isabel | I8: 1 | K8: atualização e configuração de vpn | L8: -
B9: 46147 | C9: EB1 Agpodim | E9: =IF(C9>0,LOOKUP(C9,'Lista de Escolas'!$C$3:$C$178,'Lista de Escolas'!$E$3:$E$178),"") -> #N/A | I9: 1 | K9: atualização e configuração de vpn | L9: -
B10: 46147 | C10: EB1 marinheiros | E10: =IF(C10>0,LOOKUP(C10,'Lista de Escolas'!$C$3:$C$178,'Lista de Escolas'!$E$3:$E$178),"") -> Escolas Rainha Santa Isabel | F10: 1 | K10: entrega e instalação de computador reparado
B11: 46147 | C11: EB1 Amarela | E11: =IF(C11>0,LOOKUP(C11,'Lista de Escolas'!$C$3:$C$178,'Lista de Escolas'!$E$3:$E$178),"") -> #N/A | F11: 1 | J11: 1 | K11: entrega e instalação de computador reparado e verificação de anomalias dos quadros interativos | L11: -
B12: 46148 | C12: EB1 Andrinos | E12: =IF(C12>0,LOOKUP(C12,'Lista de Escolas'!$C$3:$C$178,'Lista de Escolas'!$E$3:$E$178),"") -> #N/A | H12: 1 | K12: resolução de acesso à internet, correção de ligações erradas no switch | L12: -
B13: 46149 | C13: JI Andrinos | E13: =IF(C13>0,LOOKUP(C13,'Lista de Escolas'!$C$3:$C$178,'Lista de Escolas'!$E$3:$E$178),"") -> Escolas Rainha Santa Isabel | H13: 1 | K13: reparação de cabo de rede | L13: -
B14: 46149 | C14: EB1 Chaínça | E14: =IF(C14>0,LOOKUP(C14,'Lista de Escolas'!$C$3:$C$178,'Lista de Escolas'!$E$3:$E$178),"") -> Escolas Domingos Sequeira | I14: 1 | K14: configuração de vpn | L14: -
B15: 46150 | C15: Eb1 A-dos-Pretos | E15: =IF(C15>0,LOOKUP(C15,'Lista de Escolas'!$C$3:$C$178,'Lista de Escolas'!$E$3:$E$178),"") -> #N/A | I15: 1 | K15: configuração de vpn | L15: -
B16: 46153 | C16: JI Gândara dos Olivais | E16: =IF(C16>0,LOOKUP(C16,'Lista de Escolas'!$C$3:$C$178,'Lista de Escolas'!$E$3:$E$178),"") -> Escolas Rainha Santa Isabel | F16: 1 | I16: 1 | K16: substituição de pc. Reconfiguração de VPN
B17: 46154 | C17: Centro Escolar Maceira | E17: =IF(C17>0,LOOKUP(C17,'Lista de Escolas'!$C$3:$C$178,'Lista de Escolas'!$E$3:$E$178),"") -> #N/A | H17: 1 | J17: 1 | K17: verificação do acesso á intermnet em todas as salas de aula, ligações a Access points e ajustes de ligações no switch bastidor 2, verificação de ligações em quadros interativsos
B18: 46156 | C18: EB1 Sismaria | E18: =IF(C18>0,LOOKUP(C18,'Lista de Escolas'!$C$3:$C$178,'Lista de Escolas'!$E$3:$E$178),"") -> Escolas Rainha Santa Isabel | H18: 1 | K18: verificação da ligação à internet, abertura de pedido de reparaçãojunto do NSO
B19: 46160 | C19: JI Caldelas | E19: =IF(C19>0,LOOKUP(C19,'Lista de Escolas'!$C$3:$C$178,'Lista de Escolas'!$E$3:$E$178),"") -> Escolas Rainha Santa Isabel | H19: 1 | K19: verificação da ligação à internet, abertura de pedido de intervenção junto da Altice
B20: 18 | C20: JI Caranguejeira | E20: =IF(C20>0,LOOKUP(C20,'Lista de Escolas'!$C$3:$C$178,'Lista de Escolas'!$E$3:$E$178),"") -> Escolas Rainha Santa Isabel | H20: 1 | K20: verificação da ligação à internet, abertura de pedido de intervenção junto da Altice
B21: 46161 | C21: JI Outeiro da Fonte | E21: =IF(C21>0,LOOKUP(C21,'Lista de Escolas'!$C$3:$C$178,'Lista de Escolas'!$E$3:$E$178),"") -> Escolas Rainha Santa Isabel | H21: 1 | K21: verificação da ligação à internet, abertura de pedido de intervenção junto da Altice
B22: 46161 | C22: JI Riba D'aves | E22: =IF(C22>0,LOOKUP(C22,'Lista de Escolas'!$C$3:$C$178,'Lista de Escolas'!$E$3:$E$178),"") -> Henrique Sommer | H22: 1 | K22: verificação da ligação à internet, abertura de pedido de intervenção junto da Altice
B23: 46161 | C23: EB1 Carreira | E23: =IF(C23>0,LOOKUP(C23,'Lista de Escolas'!$C$3:$C$178,'Lista de Escolas'!$E$3:$E$178),"") -> Escolas Domingos Sequeira | F23: 1 | K23: substituição de rato
B24: 46170 | C24: EB1 Capuchos | E24: =IF(C24>0,LOOKUP(C24,'Lista de Escolas'!$C$3:$C$178,'Lista de Escolas'!$E$3:$E$178),"") -> Escolas Domingos Sequeira | F24: 1 | G24: 1 | K24: substituição de módulos de memória num pc, formatação e instalação de todo o sofware num pc
B25: 46171 | C25: JI Barreiros | E25: =IF(C25>0,LOOKUP(C25,'Lista de Escolas'!$C$3:$C$178,'Lista de Escolas'!$E$3:$E$178),"") -> Escolas Rainha Santa Isabel | H25: 1 | K25: verificação da ligação à internet, abertura de pedido de intervenção junto da Altice
B26: 46171 | C26: ji Pocariça | E26: =IF(C26>0,LOOKUP(C26,'Lista de Escolas'!$C$3:$C$178,'Lista de Escolas'!$E$3:$E$178),"") -> Henrique Sommer | H26: 1 | K26: verificação da ligação à internet, abertura de pedido de intervenção junto da Altice
B27: 46171 | C27: EB1 Monte Real | E27: =IF(C27>0,LOOKUP(C27,'Lista de Escolas'!$C$3:$C$178,'Lista de Escolas'!$E$3:$E$178),"") -> Escolas Rainha Santa Isabel | K27: substituição de access point
B28: 46171 | C28: EB1 Capuchos | E28: =IF(C28>0,LOOKUP(C28,'Lista de Escolas'!$C$3:$C$178,'Lista de Escolas'!$E$3:$E$178),"") -> Escolas Domingos Sequeira | F28: 1 | I28: 1 | K28: substituição de módulos de memória num pc
E29: =IF(C29>0,LOOKUP(C29,'Lista de Escolas'!$C$3:$C$178,'Lista de Escolas'!$E$3:$E$178),"")
E30: =IF(C30>0,LOOKUP(C30,'Lista de Escolas'!$C$3:$C$178,'Lista de Escolas'!$E$3:$E$178),"")
E31: =IF(C31>0,LOOKUP(C31,'Lista de Escolas'!$C$3:$C$178,'Lista de Escolas'!$E$3:$E$178),"")
E32: =IF(C32>0,LOOKUP(C32,'Lista de Escolas'!$C$3:$C$178,'Lista de Escolas'!$E$3:$E$178),"")
E33: =IF(C33>0,LOOKUP(C33,'Lista de Escolas'!$C$3:$C$178,'Lista de Escolas'!$E$3:$E$178),"")
E34: =IF(C34>0,LOOKUP(C34,'Lista de Escolas'!$C$3:$C$178,'Lista de Escolas'!$E$3:$E$178),"")
E35: =IF(C35>0,LOOKUP(C35,'Lista de Escolas'!$C$3:$C$178,'Lista de Escolas'!$E$3:$E$178),"")
E36: =IF(C36>0,LOOKUP(C36,'Lista de Escolas'!$C$3:$C$178,'Lista de Escolas'!$E$3:$E$178),"")
E37: =IF(C37>0,LOOKUP(C37,'Lista de Escolas'!$C$3:$C$178,'Lista de Escolas'!$E$3:$E$178),"")
E38: =IF(C38>0,LOOKUP(C38,'Lista de Escolas'!$C$3:$C$178,'Lista de Escolas'!$E$3:$E$178),"")
E39: =IF(C39>0,LOOKUP(C39,'Lista de Escolas'!$C$3:$C$178,'Lista de Escolas'!$E$3:$E$178),"")
E40: =IF(C40>0,LOOKUP(C40,'Lista de Escolas'!$C$3:$C$178,'Lista de Escolas'!$E$3:$E$178),"")
... E59: =IF(C59>0,LOOKUP(C59,'Lista de Escolas'!$C$3:$C$178,'Lista de Escolas'!$E$3:$E$178),"")
...

Sheet JUN
B1: Assistências Nas Escolas 2026
B3: JUNHO
A4: Data Pedido | B4: swiss trans | C4: Estabelecimento | D4: Freguesia | E4: Agrupamento | F4: Hardware | G4: Software | H4: Redes | I4: VPN | J4: AudioVisual | K4: Tipo de Intervenção | L4: Material Recolhido / Abatido
B5: 46174 | C5: JI Souto do Meio | E5: =IF(C5>0,LOOKUP(C5,'Lista de Escolas'!$C$3:$C$178,'Lista de Escolas'!$E$3:$E$178),"") -> Henrique Sommer | H5: 1 | K5: Verificação do acesso á internet
B6: 46174 | C6: EB1 Chaínça | E6: =IF(C6>0,LOOKUP(C6,'Lista de Escolas'!$C$3:$C$178,'Lista de Escolas'!$E$3:$E$178),"") -> Escolas Domingos Sequeira | H6: 1 | K6: Verificação do acesso á internet, anomalias na cablagem
B7: 46174 | C7: JI Coucinheira | E7: =IF(C7>0,LOOKUP(C7,'Lista de Escolas'!$C$3:$C$178,'Lista de Escolas'!$E$3:$E$178),"") -> Escolas Rainha Santa Isabel | H7: 1 | K7: Verificação do acesso á internet
B8: 46176 | C8: EB1 Chaínça | E8: =IF(C8>0,LOOKUP(C8,'Lista de Escolas'!$C$3:$C$178,'Lista de Escolas'!$E$3:$E$178),"") -> Escolas Domingos Sequeira | H8: 1 | K8: substituição de cabo de rede
B9: 46189 | C9: JI santa catarina da serra | E9: =IF(C9>0,LOOKUP(C9,'Lista de Escolas'!$C$3:$C$178,'Lista de Escolas'!$E$3:$E$178),"") -> Henrique Sommer | H9: 1 | K9: verificação de acesso à internet, reparação de ficha de rede
B10: 46189 | C10: EB1 Agodim | E10: =IF(C10>0,LOOKUP(C10,'Lista de Escolas'!$C$3:$C$178,'Lista de Escolas'!$E$3:$E$178),"") -> #N/A | F10: 1 | G10: 1 | I10: 1 | K10: entrega de dois computadores reparados, 1 monitor 1 telcado e 1 rato, configuração de acesso à vpn, instalação de impressora
B11: 46189 | C11: EB1 A-dos-Pretos | E11: =IF(C11>0,LOOKUP(C11,'Lista de Escolas'!$C$3:$C$178,'Lista de Escolas'!$E$3:$E$178),"") -> #N/A | F11: 1 | I11: 1 | K11: substituição de rato, configuração de acesso À vpn e plataforma de assiduidade
B12: 46189 | C12: EB1 Costas | E12: =IF(C12>0,LOOKUP(C12,'Lista de Escolas'!$C$3:$C$178,'Lista de Escolas'!$E$3:$E$178),"") -> Escolas Domingos Sequeira | F12: 1 | I12: 1 | J12: 1 | K12: verificação de funciobnamento de splitter, configuração de acesso à vpn e plataforma de ssiduidade
B13: 46189 | C13: EB1 Marinheiros | E13: =IF(C13>0,LOOKUP(C13,'Lista de Escolas'!$C$3:$C$178,'Lista de Escolas'!$E$3:$E$178),"") -> Escolas Rainha Santa Isabel | G13: 1 | H13: 1 | J13: 1 | K13: Instalação e conmfiguração de imporessora, restabelecimento do acesso à internet na biblioteca, e verificação de quadro interativo | L13: uadro interativo
B14: 46191 | C14: EB1 Agodim | E14: =IF(C14>0,LOOKUP(C14,'Lista de Escolas'!$C$3:$C$178,'Lista de Escolas'!$E$3:$E$178),"") -> #N/A | F14: 1 | H14: 1 | J14: 1 | K14: reconfiguração de acesso à rede fixa num pc, reconfiguração da vpn e acesso à plataforma de assiduidade
B15: 46191 | C15: EB1 Monte Redondo | E15: =IF(C15>0,LOOKUP(C15,'Lista de Escolas'!$C$3:$C$178,'Lista de Escolas'!$E$3:$E$178),"") -> Escolas Rainha Santa Isabel | G15: 1 | H15: 1 | I15: 1 | K15: entrega de dois computadores reparados, 1 monitor 1 telcado e 1 rato
B16: 46191 | C16: JI Coucinheira | E16: =IF(C16>0,LOOKUP(C16,'Lista de Escolas'!$C$3:$C$178,'Lista de Escolas'!$E$3:$E$178),"") -> Escolas Rainha Santa Isabel | F16: 1 | K16: restabelecimento de acesso à internet no Piso 1, instalação de antena no refeitório
B17: 46191 | C17: CE Parceiros | E17: =IF(C17>0,LOOKUP(C17,'Lista de Escolas'!$C$3:$C$178,'Lista de Escolas'!$E$3:$E$178),"") -> #N/A | H17: 1 | K17: verificação do acesso à rede no 1º andar do centro escolar
B18: 46202 | C18: JI santa catarina da serra | E18: =IF(C18>0,LOOKUP(C18,'Lista de Escolas'!$C$3:$C$178,'Lista de Escolas'!$E$3:$E$178),"") -> Henrique Sommer | H18: 1 | K18: passagem de cabo de rede entre salas para expansão da rede ethernet
B19: 46202 | C19: JI Outeiro da Fonte | E19: =IF(C19>0,LOOKUP(C19,'Lista de Escolas'!$C$3:$C$178,'Lista de Escolas'!$E$3:$E$178),"") -> Escolas Rainha Santa Isabel | H19: 1 | K19: verifica;\ao do estado do acesso àinternet
E20: =IF(C20>0,LOOKUP(C20,'Lista de Escolas'!$C$3:$C$178,'Lista de Escolas'!$E$3:$E$178),"")
E21: =IF(C21>0,LOOKUP(C21,'Lista de Escolas'!$C$3:$C$178,'Lista de Escolas'!$E$3:$E$178),"")
E22: =IF(C22>0,LOOKUP(C22,'Lista de Escolas'!$C$3:$C$178,'Lista de Escolas'!$E$3:$E$178),"")
E23: =IF(C23>0,LOOKUP(C23,'Lista de Escolas'!$C$3:$C$178,'Lista de Escolas'!$E$3:$E$178),"")
E24: =IF(C24>0,LOOKUP(C24,'Lista de Escolas'!$C$3:$C$178,'Lista de Escolas'!$E$3:$E$178),"")
E25: =IF(C25>0,LOOKUP(C25,'Lista de Escolas'!$C$3:$C$178,'Lista de Escolas'!$E$3:$E$178),"")
E26: =IF(C26>0,LOOKUP(C26,'Lista de Escolas'!$C$3:$C$178,'Lista de Escolas'!$E$3:$E$178),"")
E27: =IF(C27>0,LOOKUP(C27,'Lista de Escolas'!$C$3:$C$178,'Lista de Escolas'!$E$3:$E$178),"")
E28: =IF(C28>0,LOOKUP(C28,'Lista de Escolas'!$C$3:$C$178,'Lista de Escolas'!$E$3:$E$178),"")
E29: =IF(C29>0,LOOKUP(C29,'Lista de Escolas'!$C$3:$C$178,'Lista de Escolas'!$E$3:$E$178),"")
E30: =IF(C30>0,LOOKUP(C30,'Lista de Escolas'!$C$3:$C$178,'Lista de Escolas'!$E$3:$E$178),"")
E31: =IF(C31>0,LOOKUP(C31,'Lista de Escolas'!$C$3:$C$178,'Lista de Escolas'!$E$3:$E$178),"")
... E57: =IF(C57>0,LOOKUP(C57,'Lista de Escolas'!$C$3:$C$178,'Lista de Escolas'!$E$3:$E$178),"")
E58: =IF(C58>0,LOOKUP(C58,'Lista de Escolas'!$C$3:$C$178,'Lista de Escolas'!$E$3:$E$178),"") | F58: Hardware | G58: Software | H58: Redes | I58: VPN | J58: AudioVisual
E59: =IF(C59>0,LOOKUP(C59,'Lista de Escolas'!$C$3:$C$178,'Lista de Escolas'!$E$3:$E$178),"") | F59: =SUM(F5:F47) -> 5 | G59: =SUM(G5:G47) -> 3 | H59: =SUM(H5:H47) -> 11 | I59: =SUM(I5:I47) -> 4 | J59: =SUM(J5:J47) -> 3
B61: Tot. Visitas | C61: Escolas Rainha Santa Isabel | E61: =COUNTIFS(E3:E58,"=Escolas Rainha Santa Isabel") -> 5
B62: =COUNT(B5:B60) -> 15 | C62: Escolas Dr. Correia Mateus | E62: =COUNTIFS(E3:E51,"=Escolas Dr. Correia Mateus") -> 0
C63: Escolas da Caranguejeira - Santa Catarina da Serra | E63: =COUNTIFS(E3:E51,"=Escolas da Caranguejeira - Santa Catarina da Serra") -> 0
C64: Escolas de Colmeias | E64: =COUNTIFS(E3:E51,"=Escolas de Colmeias") -> 0
C65: Escolas de Marrazes | E65: =COUNTIFS(E3:E51,"=Escolas de Marrazes") -> 0
C66: Escolas Domingos Sequeira | E66: =COUNTIFS(E3:E51,"=Escolas Domingos Sequeira") -> 3
C67: Escolas D. Dinis | E67: =COUNTIFS(E3:E51,"=Escolas D. Dinis") -> 0
...

Sheet JUL
B1: Assistências Nas Escolas 2026
B3: JULHO
A4: Data Pedido | B4: Data | C4: Estabelecimento | D4: Freguesia | E4: Agrupamento | F4: Hardware | G4: Software | H4: Redes | I4: VPN | J4: AudioVisual | K4: Tipo de Intervenção | L4: Material Recolhido / Abatido
B5: 46205 | C5: JI Coucinheira | E5: =IF(C5>0,LOOKUP(C5,'Lista de Escolas'!$C$3:$C$176,'Lista de Escolas'!$E$3:$E$176),"") -> Escolas Rainha Santa Isabel | F5: 1 | I5: 1 | K5: substituição do portatil das auxiliares, configiuração de vpn | L5: 10 computadores fixos INSYS
B6: 46212 | C6: Ji A-dos-Pretos | E6: =IF(C6>0,LOOKUP(C6,'Lista de Escolas'!$C$3:$C$176,'Lista de Escolas'!$E$3:$E$176),"") -> Escolas Rainha Santa Isabel | G6: 1 | H6: 1 | K6: configuração de impressora/fotocopiadora em 3 computadores, resolução de problemas no acesso à rede wifi num pc | L6: -
B7: 46212 | C7: EB1 Porto Carro | E7: =IF(C7>0,LOOKUP(C7,'Lista de Escolas'!$C$3:$C$176,'Lista de Escolas'!$E$3:$E$176),"") -> Escolas Rainha Santa Isabel | F7: 1 | H7: 1 | K7: substituição e coniguração de access point
B8: 46216 | C8: EB1 Carriera | E8: =IF(C8>0,LOOKUP(C8,'Lista de Escolas'!$C$3:$C$176,'Lista de Escolas'!$E$3:$E$176),"") -> Escolas Domingos Sequeira | F8: 1 | J8: 1 | K8: Instalação de dois adaptadores HDMI/DVI e configurações de dois quadros interativos
B9: 46216 | C9: EB1 Vidigal | E9: =IF(C9>0,LOOKUP(C9,'Lista de Escolas'!$C$3:$C$176,'Lista de Escolas'!$E$3:$E$176),"") -> Escolas Rainha Santa Isabel | H9: 1 | K9: asferição das necessidades de equipamento de rede para dotar a nova sala com internet
B10: 46217 | C10: EB1 Carreira | E10: =IF(C10>0,LOOKUP(C10,'Lista de Escolas'!$C$3:$C$176,'Lista de Escolas'!$E$3:$E$176),"") -> Escolas Domingos Sequeira | F10: 1 | J10: 1 | K10: instalação e configuiração de um splitter VGS e confiuração de quadro interativo
B11: 46217 | C11: EB1 Bidoeira de Cima | E11: =IF(C11>0,LOOKUP(C11,'Lista de Escolas'!$C$3:$C$176,'Lista de Escolas'!$E$3:$E$176),"") -> Escolas Domingos Sequeira
E12: =IF(C12>0,LOOKUP(C12,'Lista de Escolas'!$C$3:$C$176,'Lista de Escolas'!$E$3:$E$176),"")
E13: =IF(C13>0,LOOKUP(C13,'Lista de Escolas'!$C$3:$C$176,'Lista de Escolas'!$E$3:$E$176),"")
E14: =IF(C14>0,LOOKUP(C14,'Lista de Escolas'!$C$3:$C$176,'Lista de Escolas'!$E$3:$E$176),"")
E15: =IF(C15>0,LOOKUP(C15,'Lista de Escolas'!$C$3:$C$176,'Lista de Escolas'!$E$3:$E$176),"")
E16: =IF(C16>0,LOOKUP(C16,'Lista de Escolas'!$C$3:$C$176,'Lista de Escolas'!$E$3:$E$176),"")
E17: =IF(C17>0,LOOKUP(C17,'Lista de Escolas'!$C$3:$C$176,'Lista de Escolas'!$E$3:$E$176),"")
E18: =IF(C18>0,LOOKUP(C18,'Lista de Escolas'!$C$3:$C$176,'Lista de Escolas'!$E$3:$E$176),"")
E19: =IF(C19>0,LOOKUP(C19,'Lista de Escolas'!$C$3:$C$176,'Lista de Escolas'!$E$3:$E$176),"")
E20: =IF(C20>0,LOOKUP(C20,'Lista de Escolas'!$C$3:$C$176,'Lista de Escolas'!$E$3:$E$176),"")
E21: =IF(C21>0,LOOKUP(C21,'Lista de Escolas'!$C$3:$C$176,'Lista de Escolas'!$E$3:$E$176),"")
E22: =IF(C22>0,LOOKUP(C22,'Lista de Escolas'!$C$3:$C$176,'Lista de Escolas'!$E$3:$E$176),"")
E23: =IF(C23>0,LOOKUP(C23,'Lista de Escolas'!$C$3:$C$176,'Lista de Escolas'!$E$3:$E$176),"")
... E47: =IF(C47>0,LOOKUP(C47,'Lista de Escolas'!$C$3:$C$176,'Lista de Escolas'!$E$3:$E$176),"")
E48: =IF(C48>0,LOOKUP(C48,'Lista de Escolas'!$C$3:$C$178,'Lista de Escolas'!$E$3:$E$178),"")
E49: =IF(C49>0,LOOKUP(C49,'Lista de Escolas'!$C$3:$C$178,'Lista de Escolas'!$E$3:$E$178),"")
E50: =IF(C50>0,LOOKUP(C50,'Lista de Escolas'!$C$3:$C$178,'Lista de Escolas'!$E$3:$E$178),"")
E51: =IF(C51>0,LOOKUP(C51,'Lista de Escolas'!$C$3:$C$178,'Lista de Escolas'!$E$3:$E$178),"")
E52: =IF(C52>0,LOOKUP(C52,'Lista de Escolas'!$C$3:$C$178,'Lista de Escolas'!$E$3:$E$178),"")
E53: =IF(C53>0,LOOKUP(C53,'Lista de Escolas'!$C$3:$C$178,'Lista de Escolas'!$E$3:$E$178),"")
E54: =IF(C54>0,LOOKUP(C54,'Lista de Escolas'!$C$3:$C$178,'Lista de Escolas'!$E$3:$E$178),"")
E55: =IF(C55>0,LOOKUP(C55,'Lista de Escolas'!$C$3:$C$178,'Lista de Escolas'!$E$3:$E$178),"")
E56: =IF(C56>0,LOOKUP(C56,'Lista de Escolas'!$C$3:$C$178,'Lista de Escolas'!$E$3:$E$178),"")
E57: =IF(C57>0,LOOKUP(C57,'Lista de Escolas'!$C$3:$C$178,'Lista de Escolas'!$E$3:$E$178),"")
E58: =IF(C58>0,LOOKUP(C58,'Lista de Escolas'!$C$3:$C$178,'Lista de Escolas'!$E$3:$E$178),"")
F59: Hardware | G59: Software | H59: Redes | I59: VPN | J59: AudioVisual
B60: Tot. Visitas | C60: Escolas Rainha Santa Isabel | E60: =COUNTIFS(E3:E50,"=Escolas Rainha Santa Isabel") -> 4 | F60: =SUM(F5:F48) -> 4 | G60: =SUM(G5:G48) -> 1 | H60: =SUM(H5:H48) -> 3 | I60: =SUM(I5:I48) -> 1 | J60: =SUM(J5:J48) -> 2
B61: =COUNT(B6:B59) -> 6 | C61: Escolas Dr. Correia Mateus | E61: =COUNTIFS(E3:E50,"=Escolas Dr. Correia Mateus") -> 0
C62: Escolas da Caranguejeira - Santa Catarina da Serra | E62: =COUNTIFS(E3:E50,"=Escolas da Caranguejeira - Santa Catarina da Serra") -> 0
C63: Escolas de Colmeias | E63: =COUNTIFS(E3:E50,"=Escolas de Colmeias") -> 0
C64: Escolas de Marrazes | E64: =COUNTIFS(E3:E50,"=Escolas de Marrazes") -> 0
...

Sheet AGO
B1: Assistências Nas Escolas 2026
B3: AGOSTO
A4: Data Pedido | B4: Data | C4: Estabelecimento | D4: Freguesia | E4: Agrupamento | F4: Hardware | G4: Software | H4: Redes | I4: VPN | J4: AudioVisual | K4: Tipo de Intervenção | L4: Material Recolhido / Abatido
C5: JI Courelas | E5: =SET!E5=IF(C5>0,LOOKUP(C5,'Lista de Escolas'!$C$3:$C$176,'Lista de Escolas'!$E$3:$E$176),"") -> FALSE
E6: =IF(C6>0,LOOKUP(C6,'Lista de Escolas'!$C$3:$C$178,'Lista de Escolas'!$E$3:$E$178),"")
E7: =IF(C7>0,LOOKUP(C7,'Lista de Escolas'!$C$3:$C$178,'Lista de Escolas'!$E$3:$E$178),"")
E8: =IF(C8>0,LOOKUP(C8,'Lista de Escolas'!$C$3:$C$178,'Lista de Escolas'!$E$3:$E$178),"")
E9: =IF(C9>0,LOOKUP(C9,'Lista de Escolas'!$C$3:$C$178,'Lista de Escolas'!$E$3:$E$178),"")
E10: =IF(C10>0,LOOKUP(C10,'Lista de Escolas'!$C$3:$C$178,'Lista de Escolas'!$E$3:$E$178),"")
E11: =IF(C11>0,LOOKUP(C11,'Lista de Escolas'!$C$3:$C$178,'Lista de Escolas'!$E$3:$E$178),"")
E12: =IF(C12>0,LOOKUP(C12,'Lista de Escolas'!$C$3:$C$178,'Lista de Escolas'!$E$3:$E$178),"")
E13: =IF(C13>0,LOOKUP(C13,'Lista de Escolas'!$C$3:$C$178,'Lista de Escolas'!$E$3:$E$178),"")
E14: =IF(C14>0,LOOKUP(C14,'Lista de Escolas'!$C$3:$C$178,'Lista de Escolas'!$E$3:$E$178),"")
E15: =IF(C15>0,LOOKUP(C15,'Lista de Escolas'!$C$3:$C$178,'Lista de Escolas'!$E$3:$E$178),"")
E16: =IF(C16>0,LOOKUP(C16,'Lista de Escolas'!$C$3:$C$178,'Lista de Escolas'!$E$3:$E$178),"")
E17: =IF(C17>0,LOOKUP(C17,'Lista de Escolas'!$C$3:$C$178,'Lista de Escolas'!$E$3:$E$178),"")
... E58: =IF(C58>0,LOOKUP(C58,'Lista de Escolas'!$C$3:$C$178,'Lista de Escolas'!$E$3:$E$178),"")
E59: =IF(C57>0,LOOKUP(C57,'Lista de Escolas'!$C$3:$C$178,'Lista de Escolas'!$E$3:$E$178),"")
B60: Tot. Visitas | E60: =COUNTIFS(E3:E50,"=Escolas Rainha Santa Isabel") -> 0 | J60: Escolas Rainha Santa Isabel
B61: =COUNT(B5:B59) -> 0 | E61: =COUNTIFS(E3:E50,"=Escolas Dr. Correia Mateus") -> 0 | J61: Escolas Dr. Correia Mateus
E62: =COUNTIFS(E3:E50,"=Escolas da Caranguejeira - Santa Catarina da Serra") -> 0 | J62: Escolas da Caranguejeira - Santa Catarina da Serra
E63: =COUNTIFS(E3:E50,"=Escolas de Colmeias") -> 0 | J63: Escolas de Colmeias
E64: =COUNTIFS(E3:E50,"=Escolas de Marrazes") -> 0 | J64: Escolas de Marrazes
E65: =COUNTIFS(E3:E50,"=Escolas Domingos Sequeira") -> 0 | J65: Escolas Domingos Sequeira
E66: =COUNTIFS(E3:E50,"=Escolas D. Dinis") -> 0 | J66: Escolas D. Dinis
E67: =COUNTIFS(E4:E51,"=Henrique Sommer") -> 0 | J67: Escolas Maceira
E68: =SUM(E60:E67) -> 0 | J68: Total

Sheet SET
B1: Assistências Nas Escolas 2026
B3: SETEMBRO
A4: Data Pedido | B4: Data | C4: Estabelecimento | D4: Freguesia | E4: Agrupamento | F4: Hardware | G4: Software | H4: Redes | I4: VPN | J4: AudioVisual | K4: Tipo de Intervenção | L4: Material Recolhido / Abatido
E5: =IF(C5>0,LOOKUP(C5,'Lista de Escolas'!$C$3:$C$176,'Lista de Escolas'!$E$3:$E$176),"") | L5: 10 computadores ficos INSYS
E6: =IF(C6>0,LOOKUP(C6,'Lista de Escolas'!$C$3:$C$176,'Lista de Escolas'!$E$3:$E$176),"")
E7: =IF(C7>0,LOOKUP(C7,'Lista de Escolas'!$C$3:$C$176,'Lista de Escolas'!$E$3:$E$176),"")
E8: =IF(C8>0,LOOKUP(C8,'Lista de Escolas'!$C$3:$C$176,'Lista de Escolas'!$E$3:$E$176),"")
E9: =IF(C9>0,LOOKUP(C9,'Lista de Escolas'!$C$3:$C$176,'Lista de Escolas'!$E$3:$E$176),"")
E10: =IF(C10>0,LOOKUP(C10,'Lista de Escolas'!$C$3:$C$176,'Lista de Escolas'!$E$3:$E$176),"")
E11: =IF(C11>0,LOOKUP(C11,'Lista de Escolas'!$C$3:$C$176,'Lista de Escolas'!$E$3:$E$176),"")
E12: =IF(C12>0,LOOKUP(C12,'Lista de Escolas'!$C$3:$C$176,'Lista de Escolas'!$E$3:$E$176),"")
E13: =IF(C13>0,LOOKUP(C13,'Lista de Escolas'!$C$3:$C$176,'Lista de Escolas'!$E$3:$E$176),"")
E14: =IF(C14>0,LOOKUP(C14,'Lista de Escolas'!$C$3:$C$176,'Lista de Escolas'!$E$3:$E$176),"")
E15: =IF(C15>0,LOOKUP(C15,'Lista de Escolas'!$C$3:$C$176,'Lista de Escolas'!$E$3:$E$176),"")
E16: =IF(C16>0,LOOKUP(C16,'Lista de Escolas'!$C$3:$C$176,'Lista de Escolas'!$E$3:$E$176),"")
E17: =IF(C17>0,LOOKUP(C17,'Lista de Escolas'!$C$3:$C$176,'Lista de Escolas'!$E$3:$E$176),"")
... E56: =IF(C56>0,LOOKUP(C56,'Lista de Escolas'!$C$3:$C$176,'Lista de Escolas'!$E$3:$E$176),"")
E57: =IF(C57>0,LOOKUP(C57,'Lista de Escolas'!$C$3:$C$178,'Lista de Escolas'!$E$3:$E$178),"")
B59: Tot. Visitas | E59: =COUNTIFS(E5:E49,"=Escolas Rainha Santa Isabel") -> 0 | J59: Escolas Rainha Santa Isabel
B60: =COUNT(B5:B58) -> 0 | E60: =COUNTIFS(E5:E49,"=Escolas Dr. Correia Mateus") -> 0 | J60: Escolas Dr. Correia Mateus
E61: =COUNTIFS(E5:E49,"=Escolas da Caranguejeira - Santa Catarina da Serra") -> 0 | J61: Escolas da Caranguejeira - Santa Catarina da Serra
E62: =COUNTIFS(E5:E49,"=Escolas de Colmeias") -> 0 | J62: Escolas de Colmeias
E63: =COUNTIFS(E5:E49,"=Escolas de Marrazes") -> 0 | J63: Escolas de Marrazes
E64: =COUNTIFS(E5:E49,"=Escolas Domingos Sequeira") -> 0 | J64: Escolas Domingos Sequeira
E65: =COUNTIFS(E5:E49,"=Escolas D. Dinis") -> 0 | J65: Escolas D. Dinis
E66: =COUNTIFS(E5:E50,"=Henrique Sommer") -> 0 | J66: Escolas Maceira
E67: =SUM(E59:E66) -> 0 | J67: Total

Sheet OUT
B1: Assistências Nas Escolas 2023
B3: OUTUBRO
A4: T]ecnico | B4: Data | C4: Estabelecimento | D4: Freguesia | E4: Agrupamento | F4: Hardware | G4: Software | H4: Redes | I4: VPN | J4: AudioVisual | K4: Tipo de Intervenção | L4: Material Recolhido / Abatido
E5: =IF(C5>0,LOOKUP(C5,'Lista de Escolas'!$C$3:$C$176,'Lista de Escolas'!$E$3:$E$176),"") | L5: -
E6: =IF(C6>0,LOOKUP(C6,'Lista de Escolas'!$C$3:$C$178,'Lista de Escolas'!$E$3:$E$178),"") | L6: -
E7: =IF(C7>0,LOOKUP(C7,'Lista de Escolas'!$C$3:$C$178,'Lista de Escolas'!$E$3:$E$178),"") | L7: -
E8: =IF(C8>0,LOOKUP(C8,'Lista de Escolas'!$C$3:$C$178,'Lista de Escolas'!$E$3:$E$178),"") | L8: -
E9: =IF(C9>0,LOOKUP(C9,'Lista de Escolas'!$C$3:$C$178,'Lista de Escolas'!$E$3:$E$178),"")
E10: =IF(C10>0,LOOKUP(C10,'Lista de Escolas'!$C$3:$C$178,'Lista de Escolas'!$E$3:$E$178),"")
E11: =IF(C11>0,LOOKUP(C11,'Lista de Escolas'!$C$3:$C$178,'Lista de Escolas'!$E$3:$E$178),"")
E12: =IF(C12>0,LOOKUP(C12,'Lista de Escolas'!$C$3:$C$178,'Lista de Escolas'!$E$3:$E$178),"")
E13: =IF(C13>0,LOOKUP(C13,'Lista de Escolas'!$C$3:$C$178,'Lista de Escolas'!$E$3:$E$178),"")
E14: =IF(C14>0,LOOKUP(C14,'Lista de Escolas'!$C$3:$C$178,'Lista de Escolas'!$E$3:$E$178),"")
E15: =IF(C15>0,LOOKUP(C15,'Lista de Escolas'!$C$3:$C$178,'Lista de Escolas'!$E$3:$E$178),"")
E16: =IF(C16>0,LOOKUP(C16,'Lista de Escolas'!$C$3:$C$178,'Lista de Escolas'!$E$3:$E$178),"")
E17: =IF(C17>0,LOOKUP(C17,'Lista de Escolas'!$C$3:$C$178,'Lista de Escolas'!$E$3:$E$178),"")
E18: =IF(C18>0,LOOKUP(C18,'Lista de Escolas'!$C$3:$C$178,'Lista de Escolas'!$E$3:$E$178),"")
E19: =IF(C19>0,LOOKUP(C19,'Lista de Escolas'!$C$3:$C$178,'Lista de Escolas'!$E$3:$E$178),"")
E20: =IF(C20>0,LOOKUP(C20,'Lista de Escolas'!$C$3:$C$178,'Lista de Escolas'!$E$3:$E$178),"")
... E25: =IF(C25>0,LOOKUP(C25,'Lista de Escolas'!$C$3:$C$178,'Lista de Escolas'!$E$3:$E$178),"")
E26: =IF(C26>0,LOOKUP(C26,'Lista de Escolas'!$C$3:$C$178,'Lista de Escolas'!$E$3:$E$178),"") | L26: Portatil "Classemate PC" (rato tactil avariado , não liga)
E27: =IF(C27>0,LOOKUP(C27,'Lista de Escolas'!$C$3:$C$178,'Lista de Escolas'!$E$3:$E$178),"")
E28: =IF(C28>0,LOOKUP(C28,'Lista de Escolas'!$C$3:$C$178,'Lista de Escolas'!$E$3:$E$178),"")
E29: =IF(C29>0,LOOKUP(C29,'Lista de Escolas'!$C$3:$C$178,'Lista de Escolas'!$E$3:$E$178),"") | L29: Recolhi o Portatil nº 130748 (bateria viciada não ligava) e substitui por o 130734)
E30: =IF(C30>0,LOOKUP(C30,'Lista de Escolas'!$C$3:$C$178,'Lista de Escolas'!$E$3:$E$178),"")
E31: =IF(C31>0,LOOKUP(C31,'Lista de Escolas'!$C$3:$C$178,'Lista de Escolas'!$E$3:$E$178),"") | L31: ,
E32: =IF(C32>0,LOOKUP(C32,'Lista de Escolas'!$C$3:$C$178,'Lista de Escolas'!$E$3:$E$178),"")
E33: =IF(C33>0,LOOKUP(C33,'Lista de Escolas'!$C$3:$C$178,'Lista de Escolas'!$E$3:$E$178),"")
E34: =IF(C34>0,LOOKUP(C34,'Lista de Escolas'!$C$3:$C$178,'Lista de Escolas'!$E$3:$E$178),"")
E35: =IF(C35>0,LOOKUP(C35,'Lista de Escolas'!$C$3:$C$178,'Lista de Escolas'!$E$3:$E$178),"")
E36: =IF(C36>0,LOOKUP(C36,'Lista de Escolas'!$C$3:$C$178,'Lista de Escolas'!$E$3:$E$178),"")
E37: =IF(C37>0,LOOKUP(C37,'Lista de Escolas'!$C$3:$C$178,'Lista de Escolas'!$E$3:$E$178),"")
E38: =IF(C38>0,LOOKUP(C38,'Lista de Escolas'!$C$3:$C$178,'Lista de Escolas'!$E$3:$E$178),"")
E39: =IF(C39>0,LOOKUP(C39,'Lista de Escolas'!$C$3:$C$178,'Lista de Escolas'!$E$3:$E$178),"")
E40: =IF(C40>0,LOOKUP(C40,'Lista de Escolas'!$C$3:$C$178,'Lista de Escolas'!$E$3:$E$178),"")
E41: =IF(C41>0,LOOKUP(C41,'Lista de Escolas'!$C$3:$C$178,'Lista de Escolas'!$E$3:$E$178),"")
E42: =IF(C42>0,LOOKUP(C42,'Lista de Escolas'!$C$3:$C$178,'Lista de Escolas'!$E$3:$E$178),"")
E43: =IF(C43>0,LOOKUP(C43,'Lista de Escolas'!$C$3:$C$178,'Lista de Escolas'!$E$3:$E$178),"")
... E61: =IF(C61>0,LOOKUP(C61,'Lista de Escolas'!$C$3:$C$178,'Lista de Escolas'!$E$3:$E$178),"")
B63: Tot. Visitas | E63: =COUNTIFS(E5:E53,"=Escolas Rainha Santa Isabel") -> 0 | J63: Escolas Rainha Santa Isabel
...

Sheet NOV
B1: Assistências Nas Escolas 2026
B3: NOVEMBRO
A4: Data Pedido | B4: Data | C4: Estabelecimento | D4: Agrupamento | E4: Freguesia | F4: Hardware | G4: Software | H4: Redes | I4: VPN | J4: AudioVisual | K4: Material Recolhido / Abatido
D5: =IF(C5>0,LOOKUP(C5,'Lista de Escolas'!$C$2:$C$178,'Lista de Escolas'!$E$2:$E$178),"") | K5: -
D6: =IF(C6>0,LOOKUP(C6,'Lista de Escolas'!$C$2:$C$178,'Lista de Escolas'!$E$2:$E$178),"") | K6: -
D7: =IF(C7>0,LOOKUP(C7,'Lista de Escolas'!$C$2:$C$178,'Lista de Escolas'!$E$2:$E$178),"")
D8: =IF(C8>0,LOOKUP(C8,'Lista de Escolas'!$C$2:$C$178,'Lista de Escolas'!$E$2:$E$178),"")
D9: =IF(C9>0,LOOKUP(C9,'Lista de Escolas'!$C$2:$C$178,'Lista de Escolas'!$E$2:$E$178),"")
D10: =IF(C10>0,LOOKUP(C10,'Lista de Escolas'!$C$2:$C$178,'Lista de Escolas'!$E$2:$E$178),"")
D11: =IF(C11>0,LOOKUP(C11,'Lista de Escolas'!$C$2:$C$178,'Lista de Escolas'!$E$2:$E$178),"")
D12: =IF(C12>0,LOOKUP(C12,'Lista de Escolas'!$C$2:$C$178,'Lista de Escolas'!$E$2:$E$178),"")
D13: =IF(C13>0,LOOKUP(C13,'Lista de Escolas'!$C$2:$C$178,'Lista de Escolas'!$E$2:$E$178),"")
D14: =IF(C14>0,LOOKUP(C14,'Lista de Escolas'!$C$2:$C$178,'Lista de Escolas'!$E$2:$E$178),"")
D15: =IF(C15>0,LOOKUP(C15,'Lista de Escolas'!$C$2:$C$178,'Lista de Escolas'!$E$2:$E$178),"")
D16: =IF(C16>0,LOOKUP(C16,'Lista de Escolas'!$C$2:$C$178,'Lista de Escolas'!$E$2:$E$178),"")
D17: =IF(C17>0,LOOKUP(C17,'Lista de Escolas'!$C$3:$C$178,'Lista de Escolas'!$E$3:$E$178),"")
D18: =IF(C18>0,LOOKUP(C18,'Lista de Escolas'!$C$3:$C$178,'Lista de Escolas'!$E$3:$E$178),"")
D19: =IF(C19>0,LOOKUP(C19,'Lista de Escolas'!$C$3:$C$178,'Lista de Escolas'!$E$3:$E$178),"")
D20: =IF(C20>0,LOOKUP(C20,'Lista de Escolas'!$C$3:$C$178,'Lista de Escolas'!$E$3:$E$178),"")
D21: =IF(C21>0,LOOKUP(C21,'Lista de Escolas'!$C$3:$C$178,'Lista de Escolas'!$E$3:$E$178),"")
D22: =IF(C22>0,LOOKUP(C22,'Lista de Escolas'!$C$3:$C$178,'Lista de Escolas'!$E$3:$E$178),"")
D23: =IF(C23>0,LOOKUP(C23,'Lista de Escolas'!$C$3:$C$178,'Lista de Escolas'!$E$3:$E$178),"")
D24: =IF(C24>0,LOOKUP(C24,'Lista de Escolas'!$C$3:$C$178,'Lista de Escolas'!$E$3:$E$178),"")
D25: =IF(C25>0,LOOKUP(C25,'Lista de Escolas'!$C$3:$C$178,'Lista de Escolas'!$E$3:$E$178),"")
D26: =IF(C26>0,LOOKUP(C26,'Lista de Escolas'!$C$3:$C$178,'Lista de Escolas'!$E$3:$E$178),"")
D27: =IF(C27>0,LOOKUP(C27,'Lista de Escolas'!$C$3:$C$178,'Lista de Escolas'!$E$3:$E$178),"")
D28: =IF(C28>0,LOOKUP(C28,'Lista de Escolas'!$C$3:$C$178,'Lista de Escolas'!$E$3:$E$178),"")
... D67: =IF(C67>0,LOOKUP(C67,'Lista de Escolas'!$C$3:$C$178,'Lista de Escolas'!$E$3:$E$178),"")
B69: Tot. Visitas | D69: =COUNTIFS(D5:D59,"=Escolas Rainha Santa Isabel") -> 0 | E69: Escolas Rainha Santa Isabel
